<?xml version="1.0" ?>
<!-- =================================================================================== -->
<!-- |    This document was autogenerated by xacro from xacro/scitos_haw_schunk.xacro  | -->
<!-- |    EDITING THIS FILE BY HAND IS NOT RECOMMENDED                                 | -->
<!-- =================================================================================== -->
<robot name="scitos_haw_schunk" xmlns:xacro="http://ros.org/wiki/xacro">
  <!-- Scitos and properties -->
  <material name="black">
    <color rgba="0 0 0 1"/>
  </material>
  <material name="gray">
    <color rgba="0.15 0.15 0.15 1"/>
  </material>
  <material name="golden">
    <color rgba="0.62 0.57 0.06 1"/>
  </material>
  <material name="scitosblue">
    <color rgba=".0 .0 .4 0.7"/>
  </material>
  <material name="aluminium">
    <color rgba=".75 .75 .75 1"/>
  </material>
  <material name="yellow">
    <color rgba="1 0.94 0.14 1"/>
  </material>
  <link name="base_link">
    <!--Odometry origin, former called ScitosBase -->
    <visual>
      <origin rpy="0 0 0" xyz="-0.075 0 0.2915"/>
      <geometry>
        <cylinder length="0.583" radius="0.3085"/>
      </geometry>
      <material name="scitosblue"/>
    </visual>
    <collision>
      <origin rpy="0 0 0" xyz="-0.075 0 0.3415"/>
      <geometry>
        <cylinder length="0.683" radius="0.3702"/>
      </geometry>
    </collision>
  </link>
  <link name="tail">
    <visual>
      <geometry>
        <cylinder length="0.20" radius="0.15"/>
      </geometry>
      <material name="scitosblue"/>
    </visual>
    <collision>
      <geometry>
        <cylinder length="0.30" radius="0.25"/>
      </geometry>
    </collision>
  </link>
  <joint name="base_link_tail" type="fixed">
    <origin rpy="0 0 0" xyz="-0.375 0 0.10"/>
    <parent link="base_link"/>
    <child link="tail"/>
  </joint>
  <!-- Links macros -->
  <!-- Joints macros -->
  <joint name="arm_base_fixing" type="fixed">
    <origin rpy="0 0 0" xyz="-0.075 0 0.583"/>
    <parent link="base_link"/>
    <child link="arm_base_link"/>
  </joint>
  <joint name="arm_joint_1" type="revolute">
    <!-- ~center of base swivel joint ID20 -->
    <!-- the ~center means: both z of this and below added must equal 0.268 to match reality -->
    <origin rpy="0 0 0" xyz="0 0 0.120"/>
    <parent link="arm_base_link"/>
    <child link="arm_link_1"/>
    <axis xyz="0 0 -1"/>
    <limit effort="2" lower="-3.141593" upper="3.141593" velocity="0.437"/>
  </joint>
  <joint name="arm_joint_2" type="revolute">
    <!-- center of first pitch joint ID21 -->
    <origin rpy="1.57079632679 -1.57079632679 3.14159265359" xyz="0 0 0.148"/>
    <parent link="arm_link_1"/>
    <child link="arm_link_2"/>
    <axis xyz="0 0 -1"/>
    <limit effort="2" lower="-2.024580" upper="2.024580" velocity="0.438"/>
  </joint>
  <joint name="arm_joint_3" type="revolute">
    <!-- center of second pitch joint ID22 -->
    <origin rpy="3.14159265359 0 0" xyz="0.400 0 0"/>
    <parent link="arm_link_2"/>
    <child link="arm_link_3"/>
    <axis xyz="0 0 -1"/>
    <limit effort="2" lower="-2.740166" upper="2.740166" velocity="0.436"/>
  </joint>
  <joint name="arm_joint_4" type="revolute">
    <!-- center of third pitch joint ID23 -->
    <origin rpy="3.14159265359 0 0" xyz="0.300 0 0"/>
    <parent link="arm_link_3"/>
    <child link="arm_link_4"/>
    <axis xyz="0 0 -1"/>
    <limit effort="2" lower="-2.373644" upper="2.286380" velocity="0.486"/>
  </joint>
  <joint name="arm_joint_5" type="revolute">
    <!-- center of hand roll joint ID24 -->
    <origin rpy="0 1.57079632679 0" xyz="0.121 0 0"/>
    <parent link="arm_link_4"/>
    <child link="arm_link_5"/>
    <axis xyz="0 0 -1"/>
    <limit effort="2" lower="-3.143321" upper="3.143321" velocity="0.872"/>
  </joint>
  <joint name="gripper_fixing" type="fixed">
    <origin rpy="0 -1.57079632679 0" xyz="0 0 0.130"/>
    <parent link="arm_link_5"/>
    <child link="gripper"/>
  </joint>
  <joint name="gripper_joint_pos" type="prismatic">
    <origin rpy="3.14159265359 0 0" xyz="0 0 0"/>
    <parent link="gripper_finger_neg"/>
    <child link="gripper_finger_pos"/>
    <axis xyz="0 0 1"/>
    <limit effort="2" lower="-0.000250" upper="0.068111" velocity="0.08"/>
  </joint>
  <joint name="gripper_joint_neg" type="prismatic">
    <origin rpy="0 0 0" xyz="0.047 0 0"/>
    <parent link="gripper"/>
    <child link="gripper_finger_neg"/>
    <axis xyz="0 0 1"/>
    <limit effort="2" lower="-0.000250" upper="0.068111" velocity="0.08"/>
    <mimic joint="gripper_joint_pos" multiplier="0.5" offset="0"/>
  </joint>
  <link name="arm_base_link">
    <!-- - ->
  <visual>
    <geometry>
      <cylinder radius="0.030" length="0.100"/>
    </geometry>
    <material name="black"/>
  </visual>
  <!- - -->
  </link>
  <!-- base of arm -->
  <link name="arm_link_1">
    <visual>
      <geometry>
        <cylinder length="0.13" radius="0.05"/>
      </geometry>
      <material name="golden"/>
    </visual>
    <collision>
      <geometry>
        <cylinder length="0.118" radius="0.0833333333333"/>
      </geometry>
    </collision>
  </link>
  <!-- ~center of base swivel joint ID20 -->
  <link name="arm_link_2">
    <visual>
      <geometry>
        <cylinder length="0.13" radius="0.05"/>
      </geometry>
      <material name="golden"/>
    </visual>
    <collision>
      <geometry>
        <cylinder length="0.118" radius="0.0833333333333"/>
      </geometry>
    </collision>
  </link>
  <!-- center of first pitch joint ID21 -->
  <link name="arm_link_3">
    <visual>
      <geometry>
        <cylinder length="0.13" radius="0.05"/>
      </geometry>
      <material name="golden"/>
    </visual>
    <collision>
      <geometry>
        <cylinder length="0.118" radius="0.0833333333333"/>
      </geometry>
    </collision>
  </link>
  <!-- center of second pitch joint ID22 -->
  <link name="arm_link_4">
    <visual>
      <geometry>
        <cylinder length="0.104" radius="0.04"/>
      </geometry>
      <material name="golden"/>
    </visual>
    <collision>
      <geometry>
        <cylinder length="0.118" radius="0.0666666666667"/>
      </geometry>
    </collision>
  </link>
  <!-- center of third pitch joint ID23 -->
  <link name="arm_link_5">
    <visual>
      <geometry>
        <cylinder length="0.078" radius="0.03"/>
      </geometry>
      <material name="golden"/>
    </visual>
    <collision>
      <geometry>
        <cylinder length="0.118" radius="0.05"/>
      </geometry>
    </collision>
  </link>
  <!-- center of hand roll joint ID24 -->
  <link name="arm_base_connector">
    <visual>
      <origin xyz="0 0 0.030"/>
      <geometry>
        <cylinder length="0.060" radius="0.080"/>
      </geometry>
      <material name="black"/>
    </visual>
    <!--
  <collision>
    <geometry>
      <xacro:insert_block name="shape" />
    </geometry>
  </collision>
-->
  </link>
  <joint name="arm_base_link_arm_base_connector" type="fixed">
    <origin rpy="0 0 0" xyz="0 0 0"/>
    <parent link="arm_base_link"/>
    <child link="arm_base_connector"/>
  </joint>
  <link name="arm_link_2_connector">
    <visual>
      <origin xyz="0.2 0 0.061"/>
      <geometry>
        <box size="0.47 0.105 0.038"/>
      </geometry>
      <material name="black"/>
    </visual>
    <collision>
      <origin xyz="0.2 0 0.11"/>
      <geometry>
        <box size="0.51 0.110 0.08"/>
      </geometry>
    </collision>
  </link>
  <link name="arm_link_3_connector">
    <visual>
      <origin xyz="0.15 0 0.061"/>
      <geometry>
        <box size="0.37 0.105 0.038"/>
      </geometry>
      <material name="black"/>
    </visual>
    <collision>
      <origin xyz="0.15 0 0.11"/>
      <geometry>
        <box size="0.41 0.110 0.08"/>
      </geometry>
    </collision>
  </link>
  <joint name="arm_link_2_arm_link_2_connector" type="fixed">
    <origin rpy="0 0 0" xyz="0 0 0"/>
    <parent link="arm_link_2"/>
    <child link="arm_link_2_connector"/>
  </joint>
  <joint name="arm_link_3_arm_link_3_connector" type="fixed">
    <origin rpy="0 0 0" xyz="0 0 0"/>
    <parent link="arm_link_3"/>
    <child link="arm_link_3_connector"/>
  </joint>
  <link name="gripper">
    <visual>
      <origin rpy="0 0 0" xyz="0 0 0"/>
      <geometry>
        <box size="0.090 0.080 0.112"/>
      </geometry>
      <material name="golden"/>
    </visual>
    <collision>
      <origin xyz="0.040 0 0"/>
      <geometry>
        <box size="0.185 0.100 0.132"/>
      </geometry>
    </collision>
  </link>
  <link name="gripper_finger_pos">
    <visual>
      <!--<origin xyz="${0.047+0.035} 0 ${reflect*(gripper_space+0.010)/2}"/>-->
      <origin xyz="0.035 0 0.01"/>
      <!--offsets to set fingers ontop the gripper and beside the coordinate center-->
      <geometry>
        <box size="0.070 0.030 0.020"/>
        <!--real finger size-->
      </geometry>
      <material name="aluminium"/>
    </visual>
  </link>
  <!--<xacro:connect parent="gripper" child="gripper_finger_pos"/>-->
  <link name="gripper_finger_neg">
    <visual>
      <!--<origin xyz="${0.047+0.035} 0 ${reflect*(gripper_space+0.010)/2}"/>-->
      <origin xyz="0.035 0 0.01"/>
      <!--offsets to set fingers ontop the gripper and beside the coordinate center-->
      <geometry>
        <box size="0.070 0.030 0.020"/>
        <!--real finger size-->
      </geometry>
      <material name="aluminium"/>
    </visual>
  </link>
  <!--<xacro:connect parent="gripper" child="gripper_finger_neg"/>-->
  <link name="camera_mount">
    <visual>
      <origin rpy="0 0 0" xyz="-0.0085 0 -0.003210"/>
      <geometry>
        <box size="0.073 0.051 0.025"/>
        <!-- Werte vermessen -->
      </geometry>
      <material name="black"/>
    </visual>
    <collision>
      <geometry>
        <box size="0.090 0.070  0.030"/>
      </geometry>
    </collision>
  </link>
  <joint name="gripper_camera_mount" type="fixed">
    <origin rpy="1.57079632679 0 0" xyz="-0.011 -0.055 0"/>
    <parent link="gripper"/>
    <child link="camera_mount"/>
  </joint>
  <!-- Werte berechnet -->
  <link name="kinect">
    <visual>
      <geometry>
        <box size="0.06 0.28 0.04"/>
        <!-- Werte auf cm vermessen -->
      </geometry>
      <material name="black"/>
    </visual>
    <collision>
      <geometry>
        <box size="0.08 0.30 0.06"/>
      </geometry>
    </collision>
  </link>
  <joint name="camera_mount_kinect" type="fixed">
    <origin rpy="0 0 0" xyz="-0.015 0 0.04"/>
    <parent link="camera_mount"/>
    <child link="kinect"/>
  </joint>
  <!-- Werte auf cm vermessen -->
</robot>
