<robot xmlns:xacro="http://ros.org/wiki/xacro">



 <joint name="DH_B_1" type="fixed">
    <origin xyz="${schunk_base_offset_center} 0 ${scitos_height}" rpy="0 0 0"/>
    <parent link="base_link"/>
    <child link="DH1"/>
 </joint>
 <joint name="DH_1_2" type="revolute">
	<!-- ~center of base swivel joint ID20 -->
    <!-- the ~center means: both z of this and below added must equal 0.268 to match reality -->
    <origin xyz="0 0 0.120" rpy="0 0 0"/>
    <parent link="DH1"/>
    <child link="DH2"/>
    <axis xyz="0 0 -1" />
    <limit lower="-3.141593" upper="3.141593" effort="2" velocity="${max_vel}" />
 </joint>
 <joint name="DH_2_3" type="revolute">
	<!-- center of first pitch joint ID21 -->
    <origin xyz="0 0 0.148" rpy="${0.25*tau} ${-0.25*tau} ${0.5*tau}"/>
    <parent link="DH2"/>
    <child link="DH3"/>
    <axis xyz="0 0 -1" />
    <limit lower="-2.024580" upper="2.024580" effort="2" velocity="${max_vel}" />
 </joint>
 <joint name="DH_3_4" type="revolute">
    <!-- center of second pitch joint ID22 -->
    <origin xyz="0.400 0 0" rpy="${0.5*tau} 0 0"/>
    <parent link="DH3"/>
    <child link="DH4"/>
    <axis xyz="0 0 -1" />
    <limit lower="-2.740166" upper="2.740166" effort="2" velocity="${max_vel}" />
 </joint>
 <joint name="DH_4_5" type="revolute">
	<!-- center of third pitch joint ID23 -->
    <origin xyz="0.300 0 0" rpy="${0.5*tau} 0 0"/>
    <parent link="DH4"/>
    <child link="DH5"/>
    <axis xyz="0 0 -1" />
    <limit lower="-2.373644" upper="2.286380" effort="2" velocity="${max_vel}" />
 </joint>
 <joint name="DH_5_6" type="revolute">
	<!-- center of hand roll joint ID24 -->
    <origin xyz="0.121 0 0" rpy="0 ${0.25*tau} 0"/>
    <parent link="DH5"/>
    <child link="DH6"/>
    <axis xyz="0 0 -1" />
    <limit lower="-3.143321" upper="3.143321" effort="2" velocity="${max_vel}" />
 </joint>
 <joint name="DH_6_GR" type="fixed">
    <origin xyz="0 0 0.130" rpy="0 ${-0.25*tau} 0"/>
    <parent link="DH6"/>
    <child link="Gripper"/>
 </joint>

 <joint name="GR_Fpos" type="prismatic">
    <origin xyz="0 0 0" rpy="${0.5*tau} 0 0"/>
    <parent link="GFneg"/>
    <child link="GFpos"/>
    <axis xyz="0 0 1" />
    <limit lower="-0.000250" upper="0.068111" effort="2" velocity="0.08" />
 </joint>

 <joint name="GR_Fneg" type="prismatic">
    <origin xyz="0.047 0 0" rpy="0 0 0"/>
    <parent link="Gripper"/>
    <child link="GFneg"/>
    <axis xyz="0 0 1" />
    <limit lower="-0.000250" upper="0.068111" effort="2" velocity="0.08" />
    <mimic joint="GR_Fpos" multiplier="0.5" offset="0"/>
 </joint>

<!-- Backup: rechtsdrehende Gelenke
 <joint name="DH_B_1" type="fixed">
    <origin xyz="0 0 0.700" rpy="0 0 0"/>
    <parent link="ScitosBase"/>
    <child link="DH1"/>
    <axis xyz="0 0 1" />
    <limit lower="-3.0543" upper="3.0543" effort="2" velocity="${max_vel}" />
 </joint>
 <joint name="DH_1_2" type="revolute">
    <origin xyz="0 0 0.060" rpy="0 0 ${0.5*tau}"/>
    <parent link="DH1"/>
    <child link="DH2"/>
    <axis xyz="0 0 1" />
    <limit lower="-3.0543" upper="3.0543" effort="2" velocity="${max_vel}" />
 </joint>
 <joint name="DH_2_3" type="revolute">
    <origin xyz="0 0 0.208" rpy="${0.25*tau} ${-0.25*tau} ${0.5*tau}"/>
    <parent link="DH2"/>
    <child link="DH3"/>
    <axis xyz="0 0 1" />
    <limit lower="-3.0543" upper="3.0543" effort="2" velocity="${max_vel}" />
 </joint>
 <joint name="DH_3_4" type="revolute">
    <origin xyz="0.400 0 0" rpy="${0.5*tau} 0 0"/>
    <parent link="DH3"/>
    <child link="DH4"/>
    <axis xyz="0 0 1" />
    <limit lower="-3.0543" upper="3.0543" effort="2" velocity="${max_vel}" />
 </joint>
 <joint name="DH_4_5" type="revolute">
    <origin xyz="0.300 0 0" rpy="${0.5*tau} 0 0"/>
    <parent link="DH4"/>
    <child link="DH5"/>
    <axis xyz="0 0 1" />
    <limit lower="-3.0543" upper="3.0543" effort="2" velocity="${max_vel}" />
 </joint>
 <joint name="DH_5_6" type="revolute">
    <origin xyz="0.200 0 0" rpy="0 ${0.25*tau} 0"/>
    <parent link="DH5"/>
    <child link="DH6"/>
    <axis xyz="0 0 1" />
    <limit lower="-3.0543" upper="3.0543" effort="2" velocity="${max_vel}" />
 </joint>
-->

</robot>
